<?xml version="1.0" encoding="utf-8"?>
<!-- This URDF was automatically created by SolidWorks to URDF Exporter! Originally created by Stephen Brawner (brawner@gmail.com) 
     Commit Version: 1.5.1-0-g916b5db  Build Version: 1.5.7152.31018
     For more information, please see http://wiki.ros.org/sw_urdf_exporter -->
<robot
  name="robot_urdf">
  <link
    name="base_link">
    <inertial>
      <origin
        xyz="-0.196606459038015 0.159554076614301 -0.273511091504777"
        rpy="0 0 0" />
      <mass
        value="26.726696863159" />
      <inertia
        ixx="0.245199141981758"
        ixy="-0.00946027391407056"
        ixz="0.00114579576490531"
        iyy="0.391840709510225"
        iyz="0.00568905195018926"
        izz="0.547509775056932" />
    </inertial>
    <visual>
      <origin
        xyz="0 0 0"
        rpy="0 0 0" />
      <geometry>
        <mesh
          filename="package://robot_urdf/meshes/base_link.STL" />
      </geometry>
      <material
        name="">
        <color
          rgba="0.752941176470588 0.752941176470588 0.752941176470588 1" />
      </material>
    </visual>
    <collision>
      <origin
        xyz="0 0 0"
        rpy="0 0 0" />
      <geometry>
        <mesh
          filename="package://robot_urdf/meshes/base_link.STL" />
      </geometry>
    </collision>
  </link>
  <link
    name="wheel_F_L">
    <inertial>
      <origin
        xyz="1.07648561544771E-05 6.80263411336202E-05 -0.0503799276000488"
        rpy="0 0 0" />
      <mass
        value="1.53947593448723" />
      <inertia
        ixx="0.00231502038275002"
        ixy="1.27374968092606E-06"
        ixz="-5.49660694018323E-10"
        iyy="0.00231832385423594"
        iyz="-1.75624503670963E-08"
        izz="0.00379050648843949" />
    </inertial>
    <visual>
      <origin
        xyz="0 0 0"
        rpy="0 0 0" />
      <geometry>
        <mesh
          filename="package://robot_urdf/meshes/wheel_F_L.STL" />
      </geometry>
      <material
        name="">
        <color
          rgba="0.792156862745098 0.819607843137255 0.933333333333333 1" />
      </material>
    </visual>
    <collision>
      <origin
        xyz="0 0 0"
        rpy="0 0 0" />
      <geometry>
        <mesh
          filename="package://robot_urdf/meshes/wheel_F_L.STL" />
      </geometry>
    </collision>
  </link>
  <joint
    name="FL"
    type="continuous">
    <origin
      xyz="-0.46462 -0.08935 -0.53674"
      rpy="1.5708 -1.5708 0" />
    <parent
      link="base_link" />
    <child
      link="wheel_F_L" />
    <axis
      xyz="0 0 1" />
  </joint>
  <link
    name="wheel_B_L">
    <inertial>
      <origin
        xyz="4.79694490962412E-06 3.3175974175792E-05 -0.050620191174013"
        rpy="0 0 0" />
      <mass
        value="1.53948734867329" />
      <inertia
        ixx="0.00231467622503237"
        ixy="5.74986323218259E-07"
        ixz="1.94771618708938E-10"
        iyy="0.00231869831238149"
        iyz="9.48373648930995E-09"
        izz="0.00379052780504458" />
    </inertial>
    <visual>
      <origin
        xyz="0 0 0"
        rpy="0 0 0" />
      <geometry>
        <mesh
          filename="package://robot_urdf/meshes/wheel_B_L.STL" />
      </geometry>
      <material
        name="">
        <color
          rgba="0.792156862745098 0.819607843137255 0.933333333333333 1" />
      </material>
    </visual>
    <collision>
      <origin
        xyz="0 0 0"
        rpy="0 0 0" />
      <geometry>
        <mesh
          filename="package://robot_urdf/meshes/wheel_B_L.STL" />
      </geometry>
    </collision>
  </link>
  <joint
    name="BL"
    type="continuous">
    <origin
      xyz="-0.033116 -0.08935 -0.53677"
      rpy="1.5708 -1.5708 0" />
    <parent
      link="base_link" />
    <child
      link="wheel_B_L" />
    <axis
      xyz="0 0 1" />
  </joint>
  <link
    name="wheel_F_R">
    <inertial>
      <origin
        xyz="-7.45341515417941E-06 3.24527912957118E-05 0.0503797223334211"
        rpy="0 0 0" />
      <mass
        value="1.53948084423571" />
      <inertia
        ixx="0.00231481218460663"
        ixy="-9.29543388955514E-07"
        ixz="-2.34380420274058E-09"
        iyy="0.00231856080097748"
        iyz="1.02336674420067E-08"
        izz="0.00379052736692745" />
    </inertial>
    <visual>
      <origin
        xyz="0 0 0"
        rpy="0 0 0" />
      <geometry>
        <mesh
          filename="package://robot_urdf/meshes/wheel_F_R.STL" />
      </geometry>
      <material
        name="">
        <color
          rgba="0.792156862745098 0.819607843137255 0.933333333333333 1" />
      </material>
    </visual>
    <collision>
      <origin
        xyz="0 0 0"
        rpy="0 0 0" />
      <geometry>
        <mesh
          filename="package://robot_urdf/meshes/wheel_F_R.STL" />
      </geometry>
    </collision>
  </link>
  <joint
    name="FR"
    type="continuous">
    <origin
      xyz="-0.46462 0.39675 -0.53674"
      rpy="1.5708 -1.5708 0" />
    <parent
      link="base_link" />
    <child
      link="wheel_F_R" />
    <axis
      xyz="0 0 1" />
  </joint>
  <link
    name="wheel_B_R">
    <inertial>
      <origin
        xyz="-2.70104590549547E-06 3.33887780730874E-05 0.0506200738359986"
        rpy="0 0 0" />
      <mass
        value="1.53947586206913" />
      <inertia
        ixx="0.00231461953096603"
        ixy="-3.29901578122386E-07"
        ixz="6.46119482582403E-09"
        iyy="0.00231873867220941"
        iyz="-1.63334148362116E-08"
        izz="0.00379051740941874" />
    </inertial>
    <visual>
      <origin
        xyz="0 0 0"
        rpy="0 0 0" />
      <geometry>
        <mesh
          filename="package://robot_urdf/meshes/wheel_B_R.STL" />
      </geometry>
      <material
        name="">
        <color
          rgba="0.792156862745098 0.819607843137255 0.933333333333333 1" />
      </material>
    </visual>
    <collision>
      <origin
        xyz="0 0 0"
        rpy="0 0 0" />
      <geometry>
        <mesh
          filename="package://robot_urdf/meshes/wheel_B_R.STL" />
      </geometry>
    </collision>
  </link>
  <joint
    name="BR"
    type="continuous">
    <origin
      xyz="-0.033153 0.39725 -0.53677"
      rpy="1.5708 -1.5708 0" />
    <parent
      link="base_link" />
    <child
      link="wheel_B_R" />
    <axis
      xyz="0 0 1" />
  </joint>
  <link
    name="Link1">
    <inertial>
      <origin
        xyz="0.00516519390805298 -3.95566052726119E-07 -0.0016792926108159"
        rpy="0 0 0" />
      <mass
        value="1.94965748006371" />
      <inertia
        ixx="0.0033558938483111"
        ixy="3.60894491269772E-09"
        ixz="-0.000490266027260296"
        iyy="0.00342351141560238"
        iyz="-3.67588275306507E-09"
        izz="0.00374799670663445" />
    </inertial>
    <visual>
      <origin
        xyz="0 0 0"
        rpy="0 0 0" />
      <geometry>
        <mesh
          filename="package://robot_urdf/meshes/Link1.STL" />
      </geometry>
      <material
        name="">
        <color
          rgba="0.752941176470588 0.752941176470588 0.752941176470588 1" />
      </material>
    </visual>
    <collision>
      <origin
        xyz="0 0 0"
        rpy="0 0 0" />
      <geometry>
        <mesh
          filename="package://robot_urdf/meshes/Link1.STL" />
      </geometry>
    </collision>
  </link>
  <joint
    name="J1"
    type="continuous">
    <origin
      xyz="0 0 0.1475"
      rpy="0 0 -1.5708" />
    <parent
      link="base_link" />
    <child
      link="Link1" />
    <axis
      xyz="0 0 1" />
    <limit
      lower="-4.7124"
      upper="4.7124"
      effort="150"
      velocity="3.15" />
    <dynamics
      damping="0"
      friction="0" />
    <safety_controller
      soft_upper="4.5623"
      soft_lower="-4.5623"
      k_position="20"
      k_velocity="0" />
  </joint>
  <link
    name="Link2">
    <inertial>
      <origin
        xyz="0.166798975963922 1.47320631590959E-06 -0.0802983456188538"
        rpy="0 0 0" />
      <mass
        value="5.44943642021461" />
      <inertia
        ixx="0.00871992317958262"
        ixy="-5.4856454937054E-08"
        ixz="-1.03461993329118E-08"
        iyy="0.0140432120160902"
        iyz="3.57152574860027E-08"
        izz="0.0146920619977532" />
    </inertial>
    <visual>
      <origin
        xyz="0 0 0"
        rpy="0 0 0" />
      <geometry>
        <mesh
          filename="package://robot_urdf/meshes/Link2.STL" />
      </geometry>
      <material
        name="">
        <color
          rgba="0.752941176470588 0.752941176470588 0.752941176470588 1" />
      </material>
    </visual>
    <collision>
      <origin
        xyz="0 0 0"
        rpy="0 0 0" />
      <geometry>
        <mesh
          filename="package://robot_urdf/meshes/Link2.STL" />
      </geometry>
    </collision>
  </link>
  <joint
    name="J2"
    type="continuous">
    <origin
      xyz="0.0668 0 0"
      rpy="3.1416 -1.5708 0" />
    <parent
      link="Link1" />
    <child
      link="Link2" />
    <axis
      xyz="0 0 1" />
    <limit
      lower="-3.1416"
      upper="3.1416"
      effort="150"
      velocity="3.15" />
    <dynamics
      damping="0"
      friction="0" />
    <safety_controller
      soft_upper="2.9915"
      soft_lower="-2.9915"
      k_position="20"
      k_velocity="0" />
  </joint>
  <link
    name="Link3">
    <inertial>
      <origin
        xyz="0.163906865228972 0.000129965396235146 0.042182877508537"
        rpy="0 0 0" />
      <mass
        value="2.38409152064763" />
      <inertia
        ixx="0.00442717649200486"
        ixy="-5.95806870812063E-07"
        ixz="-4.24956917405155E-05"
        iyy="0.0105495126164853"
        iyz="-2.05730074973878E-05"
        izz="0.00353203977106911" />
    </inertial>
    <visual>
      <origin
        xyz="0 0 0"
        rpy="0 0 0" />
      <geometry>
        <mesh
          filename="package://robot_urdf/meshes/Link3.STL" />
      </geometry>
      <material
        name="">
        <color
          rgba="0.752941176470588 0.752941176470588 0.752941176470588 1" />
      </material>
    </visual>
    <collision>
      <origin
        xyz="0 0 0"
        rpy="0 0 0" />
      <geometry>
        <mesh
          filename="package://robot_urdf/meshes/Link3.STL" />
      </geometry>
    </collision>
  </link>
  <joint
    name="J3"
    type="continuous">
    <origin
      xyz="0.3336 0 0"
      rpy="0 0 0" />
    <parent
      link="Link2" />
    <child
      link="Link3" />
    <axis
      xyz="0 0 1" />
    <limit
      lower="-3.1416"
      upper="3.1416"
      effort="150"
      velocity="3.15" />
    <dynamics
      damping="0"
      friction="0" />
    <safety_controller
      soft_upper="2.9915"
      soft_lower="-2.9915"
      k_position="20"
      k_velocity="0" />
  </joint>
  <link
    name="Link4">
    <inertial>
      <origin
        xyz="6.40693201658937E-05 -4.23991766818566E-06 -0.0455850272994715"
        rpy="0 0 0" />
      <mass
        value="0.784288127694868" />
      <inertia
        ixx="0.000826321885545378"
        ixy="-5.94152792244425E-08"
        ixz="0.000112733093053267"
        iyy="0.000778159785612285"
        iyz="-1.12895437137984E-07"
        izz="0.00076519536746294" />
    </inertial>
    <visual>
      <origin
        xyz="0 0 0"
        rpy="0 0 0" />
      <geometry>
        <mesh
          filename="package://robot_urdf/meshes/Link4.STL" />
      </geometry>
      <material
        name="">
        <color
          rgba="0.752941176470588 0.752941176470588 0.752941176470588 1" />
      </material>
    </visual>
    <collision>
      <origin
        xyz="0 0 0"
        rpy="0 0 0" />
      <geometry>
        <mesh
          filename="package://robot_urdf/meshes/Link4.STL" />
      </geometry>
    </collision>
  </link>
  <joint
    name="J4"
    type="continuous">
    <origin
      xyz="0.3159 0 -0.008"
      rpy="0 0 0" />
    <parent
      link="Link3" />
    <child
      link="Link4" />
    <axis
      xyz="0 0 1" />
    <limit
      lower="-3.1416"
      upper="3.1416"
      effort="150"
      velocity="3.15" />
    <dynamics
      damping="0"
      friction="0" />
    <safety_controller
      soft_upper="2.9915"
      soft_lower="-2.9915"
      k_position="20"
      k_velocity="0" />
  </joint>
  <link
    name="Link5">
    <inertial>
      <origin
        xyz="6.4069320214466E-05 4.23991767492399E-06 0.0455850272994934"
        rpy="0 0 0" />
      <mass
        value="0.784288127694147" />
      <inertia
        ixx="0.000826321885544634"
        ixy="5.94152793307062E-08"
        ixz="-0.000112733093052943"
        iyy="0.000778159785611345"
        iyz="-1.12895436951309E-07"
        izz="0.000765195367462954" />
    </inertial>
    <visual>
      <origin
        xyz="0 0 0"
        rpy="0 0 0" />
      <geometry>
        <mesh
          filename="package://robot_urdf/meshes/Link5.STL" />
      </geometry>
      <material
        name="">
        <color
          rgba="0.752941176470588 0.752941176470588 0.752941176470588 1" />
      </material>
    </visual>
    <collision>
      <origin
        xyz="0 0 0"
        rpy="0 0 0" />
      <geometry>
        <mesh
          filename="package://robot_urdf/meshes/Link5.STL" />
      </geometry>
    </collision>
  </link>
  <joint
    name="J5"
    type="continuous">
    <origin
      xyz="0.0585 0 -0.0497"
      rpy="0 1.5708 0" />
    <parent
      link="Link4" />
    <child
      link="Link5" />
    <axis
      xyz="0 0 1" />
    <limit
      lower="-3.1416"
      upper="3.1416"
      effort="150"
      velocity="3.15" />
    <dynamics
      damping="0"
      friction="0" />
    <safety_controller
      soft_upper="2.9915"
      soft_lower="-2.9915"
      k_position="20"
      k_velocity="0" />
  </joint>
  <link
    name="Link6">
    <inertial>
      <origin
        xyz="0.0398556740619664 1.38163951512511E-05 -0.00504357182565654"
        rpy="0 0 0" />
      <mass
        value="0.807678471112217" />
      <inertia
        ixx="0.00042987957939551"
        ixy="-1.99779090599955E-06"
        ixz="-9.34852358161014E-06"
        iyy="0.000885238865325597"
        iyz="-5.45581581269392E-07"
        izz="0.00102306042134082" />
    </inertial>
    <visual>
      <origin
        xyz="0 0 0"
        rpy="0 0 0" />
      <geometry>
        <mesh
          filename="package://robot_urdf/meshes/Link6.STL" />
      </geometry>
      <material
        name="">
        <color
          rgba="0.752941176470588 0.752941176470588 0.752941176470588 1" />
      </material>
    </visual>
    <collision>
      <origin
        xyz="0 0 0"
        rpy="0 0 0" />
      <geometry>
        <mesh
          filename="package://robot_urdf/meshes/Link6.STL" />
      </geometry>
    </collision>
  </link>
  <joint
    name="J6"
    type="continuous">
    <origin
      xyz="0.11535 0 0.0497"
      rpy="0 -1.5708 0" />
    <parent
      link="Link5" />
    <child
      link="Link6" />
    <axis
      xyz="0 0 1" />
    <limit
      lower="-4.7124"
      upper="4.7124"
      effort="150"
      velocity="0" />
    <dynamics
      damping="0"
      friction="0" />
    <safety_controller
      soft_upper="4.5623"
      soft_lower="-4.5623"
      k_position="20"
      k_velocity="0" />
  </joint>
</robot>